Workbook

Sheet 明细_中心
A1: source_table | B1: Center | C1: Cases | D1: Percent
A2: see_meta | B2: Foshan | C2: 109 | D2: 0.35855263
A3: see_meta | B3: Wuhan | C3: 100 | D3: 0.32894737
A4: see_meta | B4: Xinjiang | C4: 95 | D4: 0.3125

Sheet 明细_诊断_阶段
A1: source_table | B1: Stage | C1: DiagnosisCategory | D1: Cases
A2: see_meta | B2: Admission | C2: 恶性肿瘤 | D2: 102
A3: see_meta | B3: Admission | C3: 子宫肌瘤 | D3: 47
A4: see_meta | B4: Admission | C4: 子宫内膜息肉 | D4: 46
A5: see_meta | B5: Admission | C5: 妊娠相关 | D5: 39
A6: see_meta | B6: Admission | C6: 其他/未分类 | D6: 26
A7: see_meta | B7: Admission | C7: 月经/出血异常 | D7: 21
A8: see_meta | B8: Admission | C8: 宫颈良性病变 | D8: 9
A9: see_meta | B9: Admission | C9: 子宫腺肌症 | D9: 7
A10: see_meta | B10: Admission | C10: 宫颈癌前/上皮内病变 | D10: 4
A11: see_meta | B11: Admission | C11: 炎症/感染 | D11: 2
A12: see_meta | B12: Admission | C12: 卵巢良性肿物/囊肿 | D12: 1
A13: see_meta | B13: Revised | C13: 其他/未分类 | D13: 117
... A36: see_meta | B36: Final | C36: 卵巢良性肿物/囊肿 | D36: 1

Sheet 明细_诊断_阶段_palm
A1: source_table | B1: center | C1: case_id | D1: stage4 | E1: palm_class | F1: palm_coein | G1: not_classify_reason | H1: source_sheet | I1: source_column | J1: source_path | K1: source_model | L1: source_channel | M1: source_prompt_version
A2: analysis_viz/data/raw/center_data/*/GT/*.xlsx:Sheet1[GT_Admission_Diagnosis,GT_Revised_Diagnosis,GT_Final_Diagnosis] | B2: 佛山 | C2: foshan_10 | D2: D1 | E2: 3 | F2: L-肌瘤 | H2: Sheet1 | I2: d1_palm_class|rule_adjusted | J2: analysis_viz/data/raw/center_data/佛山/GT/standardized_foshan.xlsx | K2: gemini-2.5-pro | L2: gala_api | M2: g1-llm-taxonomy-v1
A3: analysis_viz/data/raw/center_data/*/GT/*.xlsx:Sheet1[GT_Admission_Diagnosis,GT_Revised_Diagnosis,GT_Final_Diagnosis] | B3: 佛山 | C3: foshan_10 | D3: D2 | E3: 4 | F3: M-恶性/增生 | H3: Sheet1 | I3: d2_palm_class|rule_adjusted | J3: analysis_viz/data/raw/center_data/佛山/GT/standardized_foshan.xlsx | K3: gemini-2.5-pro | L3: gala_api | M3: g1-llm-taxonomy-v1
A4: analysis_viz/data/raw/center_data/*/GT/*.xlsx:Sheet1[GT_Admission_Diagnosis,GT_Revised_Diagnosis,GT_Final_Diagnosis] | B4: 佛山 | C4: foshan_10 | D4: D3 | E4: 4 | F4: M-恶性/增生 | H4: Sheet1 | I4: d3_palm_class|rule_adjusted | J4: analysis_viz/data/raw/center_data/佛山/GT/standardized_foshan.xlsx | K4: gemini-2.5-pro | L4: gala_api | M4: g1-llm-taxonomy-v1
A5: analysis_viz/data/raw/center_data/*/GT/*.xlsx:Sheet1[GT_Admission_Diagnosis,GT_Revised_Diagnosis,GT_Final_Diagnosis] | B5: 佛山 | C5: foshan_100 | D5: D1 | E5: 3 | F5: L-肌瘤 | H5: Sheet1 | I5: d1_palm_class|rule_adjusted | J5: analysis_viz/data/raw/center_data/佛山/GT/standardized_foshan.xlsx | K5: gemini-2.5-pro | L5: gala_api | M5: g1-llm-taxonomy-v1
A6: analysis_viz/data/raw/center_data/*/GT/*.xlsx:Sheet1[GT_Admission_Diagnosis,GT_Revised_Diagnosis,GT_Final_Diagnosis] | B6: 佛山 | C6: foshan_100 | D6: D2 | E6: 3 | F6: L-肌瘤 | H6: Sheet1 | I6: d2_palm_class|rule_adjusted | J6: analysis_viz/data/raw/center_data/佛山/GT/standardized_foshan.xlsx | K6: gemini-2.5-pro | L6: gala_api | M6: g1-llm-taxonomy-v1
A7: analysis_viz/data/raw/center_data/*/GT/*.xlsx:Sheet1[GT_Admission_Diagnosis,GT_Revised_Diagnosis,GT_Final_Diagnosis] | B7: 佛山 | C7: foshan_100 | D7: D3 | E7: 3 | F7: L-肌瘤 | H7: Sheet1 | I7: d3_palm_class|rule_adjusted | J7: analysis_viz/data/raw/center_data/佛山/GT/standardized_foshan.xlsx | K7: gemini-2.5-pro | L7: gala_api | M7: g1-llm-taxonomy-v1
A8: analysis_viz/data/raw/center_data/*/GT/*.xlsx:Sheet1[GT_Admission_Diagnosis,GT_Revised_Diagnosis,GT_Final_Diagnosis] | B8: 佛山 | C8: foshan_101 | D8: D1 | E8: 4 | F8: M-恶性/增生 | H8: Sheet1 | I8: d1_palm_class|rule_adjusted | J8: analysis_viz/data/raw/center_data/佛山/GT/standardized_foshan.xlsx | K8: gemini-2.5-pro | L8: gala_api | M8: g1-llm-taxonomy-v1
A9: analysis_viz/data/raw/center_data/*/GT/*.xlsx:Sheet1[GT_Admission_Diagnosis,GT_Revised_Diagnosis,GT_Final_Diagnosis] | B9: 佛山 | C9: foshan_101 | D9: D2 | E9: 4 | F9: M-恶性/增生 | H9: Sheet1 | I9: d2_palm_class|rule_adjusted | J9: analysis_viz/data/raw/center_data/佛山/GT/standardized_foshan.xlsx | K9: gemini-2.5-pro | L9: gala_api | M9: g1-llm-taxonomy-v1
A10: analysis_viz/data/raw/center_data/*/GT/*.xlsx:Sheet1[GT_Admission_Diagnosis,GT_Revised_Diagnosis,GT_Final_Diagnosis] | B10: 佛山 | C10: foshan_101 | D10: D3 | E10: 4 | F10: M-恶性/增生 | H10: Sheet1 | I10: d3_palm_class|rule_adjusted | J10: analysis_viz/data/raw/center_data/佛山/GT/standardized_foshan.xlsx | K10: gemini-2.5-pro | L10: gala_api | M10: g1-llm-taxonomy-v1
A11: analysis_viz/data/raw/center_data/*/GT/*.xlsx:Sheet1[GT_Admission_Diagnosis,GT_Revised_Diagnosis,GT_Final_Diagnosis] | B11: 佛山 | C11: foshan_102 | D11: D1 | E11: 4 | F11: M-恶性/增生 | H11: Sheet1 | I11: d1_palm_class|rule_adjusted | J11: analysis_viz/data/raw/center_data/佛山/GT/standardized_foshan.xlsx | K11: gemini-2.5-pro | L11: gala_api | M11: g1-llm-taxonomy-v1
A12: analysis_viz/data/raw/center_data/*/GT/*.xlsx:Sheet1[GT_Admission_Diagnosis,GT_Revised_Diagnosis,GT_Final_Diagnosis] | B12: 佛山 | C12: foshan_102 | D12: D2 | E12: 4 | F12: M-恶性/增生 | H12: Sheet1 | I12: d2_palm_class|rule_adjusted | J12: analysis_viz/data/raw/center_data/佛山/GT/standardized_foshan.xlsx | K12: gemini-2.5-pro | L12: gala_api | M12: g1-llm-taxonomy-v1
A13: analysis_viz/data/raw/center_data/*/GT/*.xlsx:Sheet1[GT_Admission_Diagnosis,GT_Revised_Diagnosis,GT_Final_Diagnosis] | B13: 佛山 | C13: foshan_102 | D13: D3 | E13: 4 | F13: M-恶性/增生 | H13: Sheet1 | I13: d3_palm_class|rule_adjusted | J13: analysis_viz/data/raw/center_data/佛山/GT/standardized_foshan.xlsx | K13: gemini-2.5-pro | L13: gala_api | M13: g1-llm-taxonomy-v1
... A115: analysis_viz/data/raw/center_data/*/GT/*.xlsx:Sheet1[GT_Admission_Diagnosis,GT_Revised_Diagnosis,GT_Final_Diagnosis] | B115: 佛山 | C115: foshan_34 | D115: D3 | E115: 1 | F115: P-息肉 | H115: Sheet1 | I115: d3_palm_class|rule_adjusted | J115: analysis_viz/data/raw/center_data/佛山/GT/standardized_foshan.xlsx | K115: gemini-2.5-pro | L115: gala_api | M115: g1-llm-taxonomy-v1
A116: analysis_viz/data/raw/center_data/*/GT/*.xlsx:Sheet1[GT_Admission_Diagnosis,GT_Revised_Diagnosis,GT_Final_Diagnosis] | B116: 佛山 | C116: foshan_35 | D116: D1 | E116: 9 | F116: 不适用 | G116: 妊娠相关诊断不纳入PALM-COEIN | H116: Sheet1 | I116: d1_palm_class|rule_adjusted | J116: analysis_viz/data/raw/center_data/佛山/GT/standardized_foshan.xlsx | K116: gemini-2.5-pro | L116: gala_api | M116: g1-llm-taxonomy-v1
A117: analysis_viz/data/raw/center_data/*/GT/*.xlsx:Sheet1[GT_Admission_Diagnosis,GT_Revised_Diagnosis,GT_Final_Diagnosis] | B117: 佛山 | C117: foshan_35 | D117: D2 | E117: 9 | F117: 不适用 | G117: 妊娠相关诊断不纳入PALM-COEIN | H117: Sheet1 | I117: d2_palm_class|rule_adjusted | J117: analysis_viz/data/raw/center_data/佛山/GT/standardized_foshan.xlsx | K117: gemini-2.5-pro | L117: gala_api | M117: g1-llm-taxonomy-v1
A118: analysis_viz/data/raw/center_data/*/GT/*.xlsx:Sheet1[GT_Admission_Diagnosis,GT_Revised_Diagnosis,GT_Final_Diagnosis] | B118: 佛山 | C118: foshan_35 | D118: D3 | E118: 9 | F118: 不适用 | G118: 妊娠相关诊断不纳入PALM-COEIN | H118: Sheet1 | I118: d3_palm_class|rule_adjusted | J118: analysis_viz/data/raw/center_data/佛山/GT/standardized_foshan.xlsx | K118: gemini-2.5-pro | L118: gala_api | M118: g1-llm-taxonomy-v1
A119: analysis_viz/data/raw/center_data/*/GT/*.xlsx:Sheet1[GT_Admission_Diagnosis,GT_Revised_Diagnosis,GT_Final_Diagnosis] | B119: 佛山 | C119: foshan_36 | D119: D1 | E119: 9 | F119: 不适用 | G119: 妊娠相关诊断不纳入PALM-COEIN | H119: Sheet1 | I119: d1_palm_class|rule_adjusted | J119: analysis_viz/data/raw/center_data/佛山/GT/standardized_foshan.xlsx | K119: gemini-2.5-pro | L119: gala_api | M119: g1-llm-taxonomy-v1
A120: analysis_viz/data/raw/center_data/*/GT/*.xlsx:Sheet1[GT_Admission_Diagnosis,GT_Revised_Diagnosis,GT_Final_Diagnosis] | B120: 佛山 | C120: foshan_36 | D120: D2 | E120: 9 | F120: 不适用 | G120: 妊娠相关诊断不纳入PALM-COEIN | H120: Sheet1 | I120: d2_palm_class|rule_adjusted | J120: analysis_viz/data/raw/center_data/佛山/GT/standardized_foshan.xlsx | K120: gemini-2.5-pro | L120: gala_api | M120: g1-llm-taxonomy-v1
A121: analysis_viz/data/raw/center_data/*/GT/*.xlsx:Sheet1[GT_Admission_Diagnosis,GT_Revised_Diagnosis,GT_Final_Diagnosis] | B121: 佛山 | C121: foshan_36 | D121: D3 | E121: 9 | F121: 不适用 | G121: 妊娠相关诊断不纳入PALM-COEIN | H121: Sheet1 | I121: d3_palm_class|rule_adjusted | J121: analysis_viz/data/raw/center_data/佛山/GT/standardized_foshan.xlsx | K121: gemini-2.5-pro | L121: gala_api | M121: g1-llm-taxonomy-v1
A122: analysis_viz/data/raw/center_data/*/GT/*.xlsx:Sheet1[GT_Admission_Diagnosis,GT_Revised_Diagnosis,GT_Final_Diagnosis] | B122: 佛山 | C122: foshan_37 | D122: D1 | E122: 9 | F122: 不适用 | G122: 妊娠相关诊断不纳入PALM-COEIN | H122: Sheet1 | I122: d1_palm_class|rule_adjusted | J122: analysis_viz/data/raw/center_data/佛山/GT/standardized_foshan.xlsx | K122: gemini-2.5-pro | L122: gala_api | M122: g1-llm-taxonomy-v1
A123: analysis_viz/data/raw/center_data/*/GT/*.xlsx:Sheet1[GT_Admission_Diagnosis,GT_Revised_Diagnosis,GT_Final_Diagnosis] | B123: 佛山 | C123: foshan_37 | D123: D2 | E123: 9 | F123: 不适用 | G123: 妊娠相关诊断不纳入PALM-COEIN | H123: Sheet1 | I123: d2_palm_class|rule_adjusted | J123: analysis_viz/data/raw/center_data/佛山/GT/standardized_foshan.xlsx | K123: gemini-2.5-pro | L123: gala_api | M123: g1-llm-taxonomy-v1
A124: analysis_viz/data/raw/center_data/*/GT/*.xlsx:Sheet1[GT_Admission_Diagnosis,GT_Revised_Diagnosis,GT_Final_Diagnosis] | B124: 佛山 | C124: foshan_37 | D124: D3 | E124: 1 | F124: P-息肉 | H124: Sheet1 | I124: d3_palm_class|rule_adjusted | J124: analysis_viz/data/raw/center_data/佛山/GT/standardized_foshan.xlsx | K124: gemini-2.5-pro | L124: gala_api | M124: g1-llm-taxonomy-v1
A125: analysis_viz/data/raw/center_data/*/GT/*.xlsx:Sheet1[GT_Admission_Diagnosis,GT_Revised_Diagnosis,GT_Final_Diagnosis] | B125: 佛山 | C125: foshan_38 | D125: D1 | E125: 9 | F125: N-非肿瘤 | G125: 标签归一化到N-非肿瘤 | H125: Sheet1 | I125: d1_palm_class|rule_adjusted | J125: analysis_viz/data/raw/center_data/佛山/GT/standardized_foshan.xlsx | K125: gemini-2.5-pro | L125: gala_api | M125: g1-llm-taxonomy-v1
A126: analysis_viz/data/raw/center_data/*/GT/*.xlsx:Sheet1[GT_Admission_Diagnosis,GT_Revised_Diagnosis,GT_Final_Diagnosis] | B126: 佛山 | C126: foshan_38 | D126: D2 | E126: 9 | F126: N-非肿瘤 | G126: 标签归一化到N-非肿瘤 | H126: Sheet1 | I126: d2_palm_class|rule_adjusted | J126: analysis_viz/data/raw/center_data/佛山/GT/standardized_foshan.xlsx | K126: gemini-2.5-pro | L126: gala_api | M126: g1-llm-taxonomy-v1
A127: analysis_viz/data/raw/center_data/*/GT/*.xlsx:Sheet1[GT_Admission_Diagnosis,GT_Revised_Diagnosis,GT_Final_Diagnosis] | B127: 佛山 | C127: foshan_38 | D127: D3 | E127: 9 | F127: N-非肿瘤 | G127: 标签归一化到N-非肿瘤 | H127: Sheet1 | I127: d3_palm_class|rule_adjusted | J127: analysis_viz/data/raw/center_data/佛山/GT/standardized_foshan.xlsx | K127: gemini-2.5-pro | L127: gala_api | M127: g1-llm-taxonomy-v1
A128: analysis_viz/data/raw/center_data/*/GT/*.xlsx:Sheet1[GT_Admission_Diagnosis,GT_Revised_Diagnosis,GT_Final_Diagnosis] | B128: 佛山 | C128: foshan_39 | D128: D1 | E128: 9 | F128: N-非肿瘤 | G128: 标签归一化到N-非肿瘤 | H128: Sheet1 | I128: d1_palm_class|rule_adjusted | J128: analysis_viz/data/raw/center_data/佛山/GT/standardized_foshan.xlsx | K128: gemini-2.5-pro | L128: gala_api | M128: g1-llm-taxonomy-v1
A129: analysis_viz/data/raw/center_data/*/GT/*.xlsx:Sheet1[GT_Admission_Diagnosis,GT_Revised_Diagnosis,GT_Final_Diagnosis] | B129: 佛山 | C129: foshan_39 | D129: D2 | E129: 9 | F129: N-非肿瘤 | G129: 标签归一化到N-非肿瘤 | H129: Sheet1 | I129: d2_palm_class|rule_adjusted | J129: analysis_viz/data/raw/center_data/佛山/GT/standardized_foshan.xlsx | K129: gemini-2.5-pro | L129: gala_api | M129: g1-llm-taxonomy-v1
A130: analysis_viz/data/raw/center_data/*/GT/*.xlsx:Sheet1[GT_Admission_Diagnosis,GT_Revised_Diagnosis,GT_Final_Diagnosis] | B130: 佛山 | C130: foshan_39 | D130: D3 | E130: 9 | F130: N-非肿瘤 | G130: 标签归一化到N-非肿瘤 | H130: Sheet1 | I130: d3_palm_class|rule_adjusted | J130: analysis_viz/data/raw/center_data/佛山/GT/standardized_foshan.xlsx | K130: gemini-2.5-pro | L130: gala_api | M130: g1-llm-taxonomy-v1
A131: analysis_viz/data/raw/center_data/*/GT/*.xlsx:Sheet1[GT_Admission_Diagnosis,GT_Revised_Diagnosis,GT_Final_Diagnosis] | B131: 佛山 | C131: foshan_4 | D131: D1 | E131: 1 | F131: P-息肉 | H131: Sheet1 | I131: d1_palm_class|rule_adjusted | J131: analysis_viz/data/raw/center_data/佛山/GT/standardized_foshan.xlsx | K131: gemini-2.5-pro | L131: gala_api | M131: g1-llm-taxonomy-v1
A132: analysis_viz/data/raw/center_data/*/GT/*.xlsx:Sheet1[GT_Admission_Diagnosis,GT_Revised_Diagnosis,GT_Final_Diagnosis] | B132: 佛山 | C132: foshan_4 | D132: D2 | E132: 1 | F132: P-息肉 | H132: Sheet1 | I132: d2_palm_class|rule_adjusted | J132: analysis_viz/data/raw/center_data/佛山/GT/standardized_foshan.xlsx | K132: gemini-2.5-pro | L132: gala_api | M132: g1-llm-taxonomy-v1
A133: analysis_viz/data/raw/center_data/*/GT/*.xlsx:Sheet1[GT_Admission_Diagnosis,GT_Revised_Diagnosis,GT_Final_Diagnosis] | B133: 佛山 | C133: foshan_4 | D133: D3 | E133: 4 | F133: M-恶性/增生 | H133: Sheet1 | I133: d3_palm_class|rule_adjusted | J133: analysis_viz/data/raw/center_data/佛山/GT/standardized_foshan.xlsx | K133: gemini-2.5-pro | L133: gala_api | M133: g1-llm-taxonomy-v1
A134: analysis_viz/data/raw/center_data/*/GT/*.xlsx:Sheet1[GT_Admission_Diagnosis,GT_Revised_Diagnosis,GT_Final_Diagnosis] | B134: 佛山 | C134: foshan_40 | D134: D1 | E134: 9 | F134: 不适用 | G134: 妊娠相关诊断不纳入PALM-COEIN | H134: Sheet1 | I134: d1_palm_class|rule_adjusted | J134: analysis_viz/data/raw/center_data/佛山/GT/standardized_foshan.xlsx | K134: gemini-2.5-pro | L134: gala_api | M134: g1-llm-taxonomy-v1
A135: analysis_viz/data/raw/center_data/*/GT/*.xlsx:Sheet1[GT_Admission_Diagnosis,GT_Revised_Diagnosis,GT_Final_Diagnosis] | B135: 佛山 | C135: foshan_40 | D135: D2 | E135: 9 | F135: 不适用 | G135: 妊娠相关诊断不纳入PALM-COEIN | H135: Sheet1 | I135: d2_palm_class|rule_adjusted | J135: analysis_viz/data/raw/center_data/佛山/GT/standardized_foshan.xlsx | K135: gemini-2.5-pro | L135: gala_api | M135: g1-llm-taxonomy-v1
A136: analysis_viz/data/raw/center_data/*/GT/*.xlsx:Sheet1[GT_Admission_Diagnosis,GT_Revised_Diagnosis,GT_Final_Diagnosis] | B136: 佛山 | C136: foshan_40 | D136: D3 | E136: 4 | F136: 不适用 | G136: 妊娠相关诊断不纳入PALM-COEIN | H136: Sheet1 | I136: d3_palm_class|rule_adjusted | J136: analysis_viz/data/raw/center_data/佛山/GT/standardized_foshan.xlsx | K136: gemini-2.5-pro | L136: gala_api | M136: g1-llm-taxonomy-v1
A137: analysis_viz/data/raw/center_data/*/GT/*.xlsx:Sheet1[GT_Admission_Diagnosis,GT_Revised_Diagnosis,GT_Final_Diagnosis] | B137: 佛山 | C137: foshan_41 | D137: D1 | E137: 8 | F137: I-医源性 | H137: Sheet1 | I137: d1_palm_class|rule_adjusted | J137: analysis_viz/data/raw/center_data/佛山/GT/standardized_foshan.xlsx | K137: gemini-2.5-pro | L137: gala_api | M137: g1-llm-taxonomy-v1
A138: analysis_viz/data/raw/center_data/*/GT/*.xlsx:Sheet1[GT_Admission_Diagnosis,GT_Revised_Diagnosis,GT_Final_Diagnosis] | B138: 佛山 | C138: foshan_41 | D138: D2 | E138: 8 | F138: I-医源性 | H138: Sheet1 | I138: d2_palm_class|rule_adjusted | J138: analysis_viz/data/raw/center_data/佛山/GT/standardized_foshan.xlsx | K138: gemini-2.5-pro | L138: gala_api | M138: g1-llm-taxonomy-v1
A139: analysis_viz/data/raw/center_data/*/GT/*.xlsx:Sheet1[GT_Admission_Diagnosis,GT_Revised_Diagnosis,GT_Final_Diagnosis] | B139: 佛山 | C139: foshan_41 | D139: D3 | E139: 1 | F139: P-息肉 | H139: Sheet1 | I139: d3_palm_class|rule_adjusted | J139: analysis_viz/data/raw/center_data/佛山/GT/standardized_foshan.xlsx | K139: gemini-2.5-pro | L139: gala_api | M139: g1-llm-taxonomy-v1
A140: analysis_viz/data/raw/center_data/*/GT/*.xlsx:Sheet1[GT_Admission_Diagnosis,GT_Revised_Diagnosis,GT_Final_Diagnosis] | B140: 佛山 | C140: foshan_42 | D140: D1 | E140: 9 | F140: N-非肿瘤 | G140: 标签归一化到N-非肿瘤 | H140: Sheet1 | I140: d1_palm_class|rule_adjusted | J140: analysis_viz/data/raw/center_data/佛山/GT/standardized_foshan.xlsx | K140: gemini-2.5-pro | L140: gala_api | M140: g1-llm-taxonomy-v1
A141: analysis_viz/data/raw/center_data/*/GT/*.xlsx:Sheet1[GT_Admission_Diagnosis,GT_Revised_Diagnosis,GT_Final_Diagnosis] | B141: 佛山 | C141: foshan_42 | D141: D2 | E141: 9 | F141: N-非肿瘤 | G141: 标签归一化到N-非肿瘤 | H141: Sheet1 | I141: d2_palm_class|rule_adjusted | J141: analysis_viz/data/raw/center_data/佛山/GT/standardized_foshan.xlsx | K141: gemini-2.5-pro | L141: gala_api | M141: g1-llm-taxonomy-v1
...

Sheet 明细_llm_taxonomy_病例
A1: source_table | B1: center | C1: case_id | D1: d1_palm_label | E1: d2_palm_label | F1: d3_palm_label | G1: final_icd10_code | H1: final_benign_malignant_raw | I1: final_benign_malignant | J1: surgery_plan_label | K1: postop_plan_label | L1: rehab_plan_label | M1: followup_plan_label | N1: fallback_used | O1: channel | P1: model | Q1: prompt_version | R1: source_gt_path | S1: source_gt_sheet | T1: error_tag | U1: llm_status
A2: analysis_viz/data/derived/figdata/v2_subplots/G1_dataset/G1_llm_case_taxonomy_v1.csv | B2: 佛山 | C2: foshan_10 | D2: L-肌瘤 | E2: M-恶性/增生 | F2: M-恶性/增生 | G2: C54.1 | H2: 恶性 | I2: 恶性 | J2: 手术处置 | K2: 药物/内分泌治疗 | L2: 康复/护理 | M2: 随访管理 | N2: 0 | O2: gala_api | P2: gemini-2.5-pro | Q2: g1-llm-taxonomy-v1 | R2: analysis_viz/data/raw/center_data/佛山/GT/standardized_foshan.xlsx | S2: Sheet1 | T2: NONE | U2: llm_success
A3: analysis_viz/data/derived/figdata/v2_subplots/G1_dataset/G1_llm_case_taxonomy_v1.csv | B3: 佛山 | C3: foshan_100 | D3: L-肌瘤 | E3: L-肌瘤 | F3: L-肌瘤 | G3: D25.9 | H3: 良性 | I3: 良性 | J3: 手术处置 | K3: 无/未提及 | L3: 康复/护理 | M3: 随访管理 | N3: 0 | O3: gala_api | P3: gemini-2.5-pro | Q3: g1-llm-taxonomy-v1 | R3: analysis_viz/data/raw/center_data/佛山/GT/standardized_foshan.xlsx | S3: Sheet1 | T3: NONE | U3: llm_success
A4: analysis_viz/data/derived/figdata/v2_subplots/G1_dataset/G1_llm_case_taxonomy_v1.csv | B4: 佛山 | C4: foshan_101 | D4: M-恶性/增生 | E4: M-恶性/增生 | F4: M-恶性/增生 | G4: C54.1 | H4: 恶性 | I4: 恶性 | J4: 手术处置 | K4: 手术处置 | L4: 康复/护理 | M4: 随访管理 | N4: 0 | O4: gala_api | P4: gemini-2.5-pro | Q4: g1-llm-taxonomy-v1 | R4: analysis_viz/data/raw/center_data/佛山/GT/standardized_foshan.xlsx | S4: Sheet1 | T4: NONE | U4: llm_success
A5: analysis_viz/data/derived/figdata/v2_subplots/G1_dataset/G1_llm_case_taxonomy_v1.csv | B5: 佛山 | C5: foshan_102 | D5: M-恶性/增生 | E5: M-恶性/增生 | F5: M-恶性/增生 | G5: N85.1 | H5: 恶性 | I5: 恶性 | J5: 手术处置 | K5: 无/未提及 | L5: 康复/护理 | M5: 无/未提及 | N5: 0 | O5: gala_api | P5: gemini-2.5-pro | Q5: g1-llm-taxonomy-v1 | R5: analysis_viz/data/raw/center_data/佛山/GT/standardized_foshan.xlsx | S5: Sheet1 | T5: NONE | U5: llm_success
A6: analysis_viz/data/derived/figdata/v2_subplots/G1_dataset/G1_llm_case_taxonomy_v1.csv | B6: 佛山 | C6: foshan_103 | D6: M-恶性/增生 | E6: M-恶性/增生 | F6: M-恶性/增生 | G6: N85.0 | H6: 良性 | I6: 恶性 | J6: 手术处置 | K6: 药物/内分泌治疗 | L6: 康复/护理 | M6: 随访管理 | N6: 0 | O6: gala_api | P6: gemini-2.5-pro | Q6: g1-llm-taxonomy-v1 | R6: analysis_viz/data/raw/center_data/佛山/GT/standardized_foshan.xlsx | S6: Sheet1 | T6: NONE | U6: llm_success
A7: analysis_viz/data/derived/figdata/v2_subplots/G1_dataset/G1_llm_case_taxonomy_v1.csv | B7: 佛山 | C7: foshan_104 | D7: M-恶性/增生 | E7: M-恶性/增生 | F7: M-恶性/增生 | G7: C54.1 | H7: 恶性 | I7: 恶性 | J7: 手术处置 | K7: 检查/监测 | L7: 康复/护理 | M7: 随访管理 | N7: 0 | O7: gala_api | P7: gemini-2.5-pro | Q7: g1-llm-taxonomy-v1 | R7: analysis_viz/data/raw/center_data/佛山/GT/standardized_foshan.xlsx | S7: Sheet1 | T7: NONE | U7: llm_success
A8: analysis_viz/data/derived/figdata/v2_subplots/G1_dataset/G1_llm_case_taxonomy_v1.csv | B8: 佛山 | C8: foshan_105 | D8: M-恶性/增生 | E8: M-恶性/增生 | F8: M-恶性/增生 | G8: N87.1 | H8: 未分类 | I8: 恶性 | J8: 手术处置 | K8: 无/未提及 | L8: 康复/护理 | M8: 随访管理 | N8: 0 | O8: gala_api | P8: gemini-2.5-pro | Q8: g1-llm-taxonomy-v1 | R8: analysis_viz/data/raw/center_data/佛山/GT/standardized_foshan.xlsx | S8: Sheet1 | T8: NONE | U8: llm_success
A9: analysis_viz/data/derived/figdata/v2_subplots/G1_dataset/G1_llm_case_taxonomy_v1.csv | B9: 佛山 | C9: foshan_106 | D9: L-肌瘤 | E9: L-肌瘤 | F9: L-肌瘤 | G9: D25.9 | H9: 良性 | I9: 良性 | J9: 手术处置 | K9: 无/未提及 | L9: 康复/护理 | M9: 随访管理 | N9: 0 | O9: gala_api | P9: gemini-2.5-pro | Q9: g1-llm-taxonomy-v1 | R9: analysis_viz/data/raw/center_data/佛山/GT/standardized_foshan.xlsx | S9: Sheet1 | T9: NONE | U9: llm_success
A10: analysis_viz/data/derived/figdata/v2_subplots/G1_dataset/G1_llm_case_taxonomy_v1.csv | B10: 佛山 | C10: foshan_107 | D10: P-息肉 | E10: P-息肉 | F10: P-息肉 | G10: N84.1 | H10: 良性 | I10: 良性 | J10: 手术处置 | K10: 无/未提及 | L10: 康复/护理 | M10: 无/未提及 | N10: 0 | O10: gala_api | P10: gemini-2.5-pro | Q10: g1-llm-taxonomy-v1 | R10: analysis_viz/data/raw/center_data/佛山/GT/standardized_foshan.xlsx | S10: Sheet1 | T10: NONE | U10: llm_success
A11: analysis_viz/data/derived/figdata/v2_subplots/G1_dataset/G1_llm_case_taxonomy_v1.csv | B11: 佛山 | C11: foshan_108 | D11: P-息肉 | E11: P-息肉 | F11: P-息肉 | G11: N84.1 | H11: 良性 | I11: 良性 | J11: 手术处置 | K11: 无/未提及 | L11: 康复/护理 | M11: 随访管理 | N11: 0 | O11: gala_api | P11: gemini-2.5-pro | Q11: g1-llm-taxonomy-v1 | R11: analysis_viz/data/raw/center_data/佛山/GT/standardized_foshan.xlsx | S11: Sheet1 | T11: NONE | U11: llm_success
A12: analysis_viz/data/derived/figdata/v2_subplots/G1_dataset/G1_llm_case_taxonomy_v1.csv | B12: 佛山 | C12: foshan_109 | D12: P-息肉 | E12: P-息肉 | F12: P-息肉 | G12: N84.0 | H12: 良性 | I12: 良性 | J12: 手术处置 | K12: 药物/内分泌治疗 | L12: 康复/护理 | M12: 随访管理 | N12: 0 | O12: gala_api | P12: gemini-2.5-pro | Q12: g1-llm-taxonomy-v1 | R12: analysis_viz/data/raw/center_data/佛山/GT/standardized_foshan.xlsx | S12: Sheet1 | T12: NONE | U12: llm_success
A13: analysis_viz/data/derived/figdata/v2_subplots/G1_dataset/G1_llm_case_taxonomy_v1.csv | B13: 佛山 | C13: foshan_11 | D13: M-恶性/增生 | E13: M-恶性/增生 | F13: M-恶性/增生 | G13: C54.1 | H13: 恶性 | I13: 恶性 | J13: 手术处置 | K13: 药物/内分泌治疗 | L13: 无/未提及 | M13: 随访管理 | N13: 0 | O13: gala_api | P13: gemini-2.5-pro | Q13: g1-llm-taxonomy-v1 | R13: analysis_viz/data/raw/center_data/佛山/GT/standardized_foshan.xlsx | S13: Sheet1 | T13: NONE | U13: llm_success
... A305: analysis_viz/data/derived/figdata/v2_subplots/G1_dataset/G1_llm_case_taxonomy_v1.csv | B305: 武汉 | C305: wuhan_99 | D305: P-息肉 | E305: P-息肉 | F305: P-息肉 | G305: N84.0 | H305: 良性 | I305: 良性 | J305: 手术处置 | K305: 随访管理 | L305: 随访管理 | M305: 随访管理 | N305: 0 | O305: gala_api | P305: gemini-2.5-pro | Q305: g1-llm-taxonomy-v1 | R305: analysis_viz/data/raw/center_data/武汉/GT/standardized_wuhan - 移动信息.xlsx | S305: Sheet1 | T305: NONE | U305: llm_success

Sheet 明细_中心_bm_病例
A1: source_table | B1: center | C1: case_id | D1: d1_palm_label | E1: d2_palm_label | F1: d3_palm_label | G1: final_icd10_code | H1: final_benign_malignant_raw | I1: final_benign_malignant | J1: surgery_plan_label | K1: postop_plan_label | L1: rehab_plan_label | M1: followup_plan_label | N1: fallback_used | O1: channel | P1: model | Q1: prompt_version | R1: source_gt_path | S1: source_gt_sheet | T1: error_tag | U1: llm_status | V1: benign_malignant_from_d3 | W1: bm_conflict_flag
A2: A图内圈复现明细；final_benign_malignant 基于 d3_palm_label 进行恶性兜底纠偏 | B2: 佛山 | C2: foshan_10 | D2: L-肌瘤 | E2: M-恶性/增生 | F2: M-恶性/增生 | G2: C54.1 | H2: 恶性 | I2: 恶性 | J2: 手术处置 | K2: 药物/内分泌治疗 | L2: 康复/护理 | M2: 随访管理 | N2: 0 | O2: gala_api | P2: gemini-2.5-pro | Q2: g1-llm-taxonomy-v1 | R2: analysis_viz/data/raw/center_data/佛山/GT/standardized_foshan.xlsx | S2: Sheet1 | T2: NONE | U2: llm_success | V2: 恶性 | W2: 0
A3: A图内圈复现明细；final_benign_malignant 基于 d3_palm_label 进行恶性兜底纠偏 | B3: 佛山 | C3: foshan_100 | D3: L-肌瘤 | E3: L-肌瘤 | F3: L-肌瘤 | G3: D25.9 | H3: 良性 | I3: 良性 | J3: 手术处置 | K3: 无/未提及 | L3: 康复/护理 | M3: 随访管理 | N3: 0 | O3: gala_api | P3: gemini-2.5-pro | Q3: g1-llm-taxonomy-v1 | R3: analysis_viz/data/raw/center_data/佛山/GT/standardized_foshan.xlsx | S3: Sheet1 | T3: NONE | U3: llm_success | V3: 良性 | W3: 0
A4: A图内圈复现明细；final_benign_malignant 基于 d3_palm_label 进行恶性兜底纠偏 | B4: 佛山 | C4: foshan_101 | D4: M-恶性/增生 | E4: M-恶性/增生 | F4: M-恶性/增生 | G4: C54.1 | H4: 恶性 | I4: 恶性 | J4: 手术处置 | K4: 手术处置 | L4: 康复/护理 | M4: 随访管理 | N4: 0 | O4: gala_api | P4: gemini-2.5-pro | Q4: g1-llm-taxonomy-v1 | R4: analysis_viz/data/raw/center_data/佛山/GT/standardized_foshan.xlsx | S4: Sheet1 | T4: NONE | U4: llm_success | V4: 恶性 | W4: 0
A5: A图内圈复现明细；final_benign_malignant 基于 d3_palm_label 进行恶性兜底纠偏 | B5: 佛山 | C5: foshan_102 | D5: M-恶性/增生 | E5: M-恶性/增生 | F5: M-恶性/增生 | G5: N85.1 | H5: 恶性 | I5: 恶性 | J5: 手术处置 | K5: 无/未提及 | L5: 康复/护理 | M5: 无/未提及 | N5: 0 | O5: gala_api | P5: gemini-2.5-pro | Q5: g1-llm-taxonomy-v1 | R5: analysis_viz/data/raw/center_data/佛山/GT/standardized_foshan.xlsx | S5: Sheet1 | T5: NONE | U5: llm_success | V5: 恶性 | W5: 0
A6: A图内圈复现明细；final_benign_malignant 基于 d3_palm_label 进行恶性兜底纠偏 | B6: 佛山 | C6: foshan_103 | D6: M-恶性/增生 | E6: M-恶性/增生 | F6: M-恶性/增生 | G6: N85.0 | H6: 良性 | I6: 恶性 | J6: 手术处置 | K6: 药物/内分泌治疗 | L6: 康复/护理 | M6: 随访管理 | N6: 0 | O6: gala_api | P6: gemini-2.5-pro | Q6: g1-llm-taxonomy-v1 | R6: analysis_viz/data/raw/center_data/佛山/GT/standardized_foshan.xlsx | S6: Sheet1 | T6: NONE | U6: llm_success | V6: 恶性 | W6: 0
A7: A图内圈复现明细；final_benign_malignant 基于 d3_palm_label 进行恶性兜底纠偏 | B7: 佛山 | C7: foshan_104 | D7: M-恶性/增生 | E7: M-恶性/增生 | F7: M-恶性/增生 | G7: C54.1 | H7: 恶性 | I7: 恶性 | J7: 手术处置 | K7: 检查/监测 | L7: 康复/护理 | M7: 随访管理 | N7: 0 | O7: gala_api | P7: gemini-2.5-pro | Q7: g1-llm-taxonomy-v1 | R7: analysis_viz/data/raw/center_data/佛山/GT/standardized_foshan.xlsx | S7: Sheet1 | T7: NONE | U7: llm_success | V7: 恶性 | W7: 0
A8: A图内圈复现明细；final_benign_malignant 基于 d3_palm_label 进行恶性兜底纠偏 | B8: 佛山 | C8: foshan_105 | D8: M-恶性/增生 | E8: M-恶性/增生 | F8: M-恶性/增生 | G8: N87.1 | H8: 未分类 | I8: 恶性 | J8: 手术处置 | K8: 无/未提及 | L8: 康复/护理 | M8: 随访管理 | N8: 0 | O8: gala_api | P8: gemini-2.5-pro | Q8: g1-llm-taxonomy-v1 | R8: analysis_viz/data/raw/center_data/佛山/GT/standardized_foshan.xlsx | S8: Sheet1 | T8: NONE | U8: llm_success | V8: 恶性 | W8: 0
A9: A图内圈复现明细；final_benign_malignant 基于 d3_palm_label 进行恶性兜底纠偏 | B9: 佛山 | C9: foshan_106 | D9: L-肌瘤 | E9: L-肌瘤 | F9: L-肌瘤 | G9: D25.9 | H9: 良性 | I9: 良性 | J9: 手术处置 | K9: 无/未提及 | L9: 康复/护理 | M9: 随访管理 | N9: 0 | O9: gala_api | P9: gemini-2.5-pro | Q9: g1-llm-taxonomy-v1 | R9: analysis_viz/data/raw/center_data/佛山/GT/standardized_foshan.xlsx | S9: Sheet1 | T9: NONE | U9: llm_success | V9: 良性 | W9: 0
A10: A图内圈复现明细；final_benign_malignant 基于 d3_palm_label 进行恶性兜底纠偏 | B10: 佛山 | C10: foshan_107 | D10: P-息肉 | E10: P-息肉 | F10: P-息肉 | G10: N84.1 | H10: 良性 | I10: 良性 | J10: 手术处置 | K10: 无/未提及 | L10: 康复/护理 | M10: 无/未提及 | N10: 0 | O10: gala_api | P10: gemini-2.5-pro | Q10: g1-llm-taxonomy-v1 | R10: analysis_viz/data/raw/center_data/佛山/GT/standardized_foshan.xlsx | S10: Sheet1 | T10: NONE | U10: llm_success | V10: 良性 | W10: 0
A11: A图内圈复现明细；final_benign_malignant 基于 d3_palm_label 进行恶性兜底纠偏 | B11: 佛山 | C11: foshan_108 | D11: P-息肉 | E11: P-息肉 | F11: P-息肉 | G11: N84.1 | H11: 良性 | I11: 良性 | J11: 手术处置 | K11: 无/未提及 | L11: 康复/护理 | M11: 随访管理 | N11: 0 | O11: gala_api | P11: gemini-2.5-pro | Q11: g1-llm-taxonomy-v1 | R11: analysis_viz/data/raw/center_data/佛山/GT/standardized_foshan.xlsx | S11: Sheet1 | T11: NONE | U11: llm_success | V11: 良性 | W11: 0
A12: A图内圈复现明细；final_benign_malignant 基于 d3_palm_label 进行恶性兜底纠偏 | B12: 佛山 | C12: foshan_109 | D12: P-息肉 | E12: P-息肉 | F12: P-息肉 | G12: N84.0 | H12: 良性 | I12: 良性 | J12: 手术处置 | K12: 药物/内分泌治疗 | L12: 康复/护理 | M12: 随访管理 | N12: 0 | O12: gala_api | P12: gemini-2.5-pro | Q12: g1-llm-taxonomy-v1 | R12: analysis_viz/data/raw/center_data/佛山/GT/standardized_foshan.xlsx | S12: Sheet1 | T12: NONE | U12: llm_success | V12: 良性 | W12: 0
A13: A图内圈复现明细；final_benign_malignant 基于 d3_palm_label 进行恶性兜底纠偏 | B13: 佛山 | C13: foshan_11 | D13: M-恶性/增生 | E13: M-恶性/增生 | F13: M-恶性/增生 | G13: C54.1 | H13: 恶性 | I13: 恶性 | J13: 手术处置 | K13: 药物/内分泌治疗 | L13: 无/未提及 | M13: 随访管理 | N13: 0 | O13: gala_api | P13: gemini-2.5-pro | Q13: g1-llm-taxonomy-v1 | R13: analysis_viz/data/raw/center_data/佛山/GT/standardized_foshan.xlsx | S13: Sheet1 | T13: NONE | U13: llm_success | V13: 恶性 | W13: 0
... A305: A图内圈复现明细；final_benign_malignant 基于 d3_palm_label 进行恶性兜底纠偏 | B305: 武汉 | C305: wuhan_99 | D305: P-息肉 | E305: P-息肉 | F305: P-息肉 | G305: N84.0 | H305: 良性 | I305: 良性 | J305: 手术处置 | K305: 随访管理 | L305: 随访管理 | M305: 随访管理 | N305: 0 | O305: gala_api | P305: gemini-2.5-pro | Q305: g1-llm-taxonomy-v1 | R305: analysis_viz/data/raw/center_data/武汉/GT/standardized_wuhan - 移动信息.xlsx | S305: Sheet1 | T305: NONE | U305: llm_success | V305: 良性 | W305: 0

Sheet 明细_llm_taxonomy_error_病例
A1: source_table | B1: center | C1: case_id | D1: fallback_used | E1: error_tag | F1: error | G1: channel | H1: model | I1: source_gt_path | J1: source_gt_sheet
A2: analysis_viz/data/derived/figdata/v2_subplots/G1_dataset/G1_llm_case_taxonomy_v1.csv[error,fallback_used] | B2: 佛山 | C2: foshan_85 | D2: 1 | E2: HTTP_429 | F2: 429 Client Error: Too Many Requests for url: https://yunwu.ai/v1/chat/completions | G2: gala_api | H2: gemini-2.5-pro | I2: analysis_viz/data/raw/center_data/佛山/GT/standardized_foshan.xlsx | J2: Sheet1
A3: analysis_viz/data/derived/figdata/v2_subplots/G1_dataset/G1_llm_case_taxonomy_v1.csv[error,fallback_used] | B3: 佛山 | C3: foshan_90 | D3: 1 | E3: HTTP_429 | F3: 429 Client Error: Too Many Requests for url: https://yunwu.ai/v1/chat/completions | G3: gala_api | H3: gemini-2.5-pro | I3: analysis_viz/data/raw/center_data/佛山/GT/standardized_foshan.xlsx | J3: Sheet1
A4: analysis_viz/data/derived/figdata/v2_subplots/G1_dataset/G1_llm_case_taxonomy_v1.csv[error,fallback_used] | B4: 新疆 | C4: Xinjiang_006 | D4: 1 | E4: HTTP_429 | F4: 429 Client Error: Too Many Requests for url: https://yunwu.ai/v1/chat/completions | G4: gala_api | H4: gemini-2.5-pro | I4: analysis_viz/data/raw/center_data/新疆/GT/standardized_xinjiang.xlsx | J4: Sheet1
A5: analysis_viz/data/derived/figdata/v2_subplots/G1_dataset/G1_llm_case_taxonomy_v1.csv[error,fallback_used] | B5: 新疆 | C5: Xinjiang_020 | D5: 1 | E5: HTTP_429 | F5: 429 Client Error: Too Many Requests for url: https://yunwu.ai/v1/chat/completions | G5: gala_api | H5: gemini-2.5-pro | I5: analysis_viz/data/raw/center_data/新疆/GT/standardized_xinjiang.xlsx | J5: Sheet1
A6: analysis_viz/data/derived/figdata/v2_subplots/G1_dataset/G1_llm_case_taxonomy_v1.csv[error,fallback_used] | B6: 新疆 | C6: Xinjiang_074 | D6: 1 | E6: HTTP_429 | F6: 429 Client Error: Too Many Requests for url: https://yunwu.ai/v1/chat/completions | G6: gala_api | H6: gemini-2.5-pro | I6: analysis_viz/data/raw/center_data/新疆/GT/standardized_xinjiang.xlsx | J6: Sheet1
A7: analysis_viz/data/derived/figdata/v2_subplots/G1_dataset/G1_llm_case_taxonomy_v1.csv[error,fallback_used] | B7: 新疆 | C7: Xinjiang_089 | D7: 1 | E7: HTTP_429 | F7: 429 Client Error: Too Many Requests for url: https://yunwu.ai/v1/chat/completions | G7: gala_api | H7: gemini-2.5-pro | I7: analysis_viz/data/raw/center_data/新疆/GT/standardized_xinjiang.xlsx | J7: Sheet1
A8: analysis_viz/data/derived/figdata/v2_subplots/G1_dataset/G1_llm_case_taxonomy_v1.csv[error,fallback_used] | B8: 新疆 | C8: Xinjiang_090 | D8: 1 | E8: HTTP_429 | F8: 429 Client Error: Too Many Requests for url: https://yunwu.ai/v1/chat/completions | G8: gala_api | H8: gemini-2.5-pro | I8: analysis_viz/data/raw/center_data/新疆/GT/standardized_xinjiang.xlsx | J8: Sheet1
A9: analysis_viz/data/derived/figdata/v2_subplots/G1_dataset/G1_llm_case_taxonomy_v1.csv[error,fallback_used] | B9: 武汉 | C9: wuhan_101 | D9: 1 | E9: HTTP_429 | F9: 429 Client Error: Too Many Requests for url: https://yunwu.ai/v1/chat/completions | G9: gala_api | H9: gemini-2.5-pro | I9: analysis_viz/data/raw/center_data/武汉/GT/standardized_wuhan - 移动信息.xlsx | J9: Sheet1
A10: analysis_viz/data/derived/figdata/v2_subplots/G1_dataset/G1_llm_case_taxonomy_v1.csv[error,fallback_used] | B10: 武汉 | C10: wuhan_26 | D10: 1 | E10: HTTP_429 | F10: 429 Client Error: Too Many Requests for url: https://yunwu.ai/v1/chat/completions | G10: gala_api | H10: gemini-2.5-pro | I10: analysis_viz/data/raw/center_data/武汉/GT/standardized_wuhan - 移动信息.xlsx | J10: Sheet1
A11: analysis_viz/data/derived/figdata/v2_subplots/G1_dataset/G1_llm_case_taxonomy_v1.csv[error,fallback_used] | B11: 武汉 | C11: wuhan_37 | D11: 1 | E11: HTTP_429 | F11: 429 Client Error: Too Many Requests for url: https://yunwu.ai/v1/chat/completions | G11: gala_api | H11: gemini-2.5-pro | I11: analysis_viz/data/raw/center_data/武汉/GT/standardized_wuhan - 移动信息.xlsx | J11: Sheet1
A12: analysis_viz/data/derived/figdata/v2_subplots/G1_dataset/G1_llm_case_taxonomy_v1.csv[error,fallback_used] | B12: 武汉 | C12: wuhan_39 | D12: 1 | E12: HTTP_429 | F12: 429 Client Error: Too Many Requests for url: https://yunwu.ai/v1/chat/completions | G12: gala_api | H12: gemini-2.5-pro | I12: analysis_viz/data/raw/center_data/武汉/GT/standardized_wuhan - 移动信息.xlsx | J12: Sheet1
A13: analysis_viz/data/derived/figdata/v2_subplots/G1_dataset/G1_llm_case_taxonomy_v1.csv[error,fallback_used] | B13: 武汉 | C13: wuhan_52 | D13: 1 | E13: HTTP_429 | F13: 429 Client Error: Too Many Requests for url: https://yunwu.ai/v1/chat/completions | G13: gala_api | H13: gemini-2.5-pro | I13: analysis_viz/data/raw/center_data/武汉/GT/standardized_wuhan - 移动信息.xlsx | J13: Sheet1

Sheet 明细_palm_阶段_pct_non桑基
A1: source_table | B1: P-息肉 | C1: A-腺肌症 | D1: L-肌瘤 | E1: M-恶性/增生 | F1: C-凝血相关 | G1: O-排卵障碍 | H1: E-子宫内膜原因 | I1: I-医源性 | J1: N-非肿瘤 | K1: 数据缺失 | L1: 不适用
A2: 由 detail_diag_stage_palm 按 stage4×palm_coein 汇总后标准化为百分比 | B2: 28.618421 | C2: 2.6315789 | D2: 11.513158 | E2: 30.921053 | F2: 0.32894737 | G2: 1.6447368 | H2: 0.65789474 | I2: 1.9736842 | J2: 8.5526316 | K2: 0 | L2: 13.157895
A3: 由 detail_diag_stage_palm 按 stage4×palm_coein 汇总后标准化为百分比 | B3: 26.644737 | C3: 3.6184211 | D3: 12.171053 | E3: 28.947368 | F3: 0.32894737 | G3: 1.9736842 | H3: 1.6447368 | I3: 1.6447368 | J3: 10.855263 | K3: 0 | L3: 12.171053
A4: 由 detail_diag_stage_palm 按 stage4×palm_coein 汇总后标准化为百分比 | B4: 30.921053 | C4: 4.2763158 | D4: 10.526316 | E4: 31.25 | F4: 0 | G4: 2.3026316 | H4: 3.9473684 | I4: 1.3157895 | J4: 3.9473684 | K4: 0 | L4: 11.513158

Sheet 明细_text_len
A1: source_table | B1: CaseID | C1: Center | D1: GT_Final_Diagnosis | E1: DiagnosisCategory | F1: TextLen
A2: see_meta | B2: foshan_3 | C2: Foshan | D2: 最终诊断::1.子宫内膜增生不伴不典型增生 2.子宫内膜息肉 | E2: 子宫内膜息肉 | F2: 966
A3: see_meta | B3: foshan_4 | C3: Foshan | D3: 最终诊断::1.不伴不典型增生的子宫内膜增生 2.子宫内膜息肉 | E3: 子宫内膜息肉 | F3: 1132
A4: see_meta | B4: foshan_5 | C4: Foshan | D4: 最终诊断::1.异常子宫出血：子宫内膜增生不伴不典型增生 2、子宫内膜息肉 | E4: 子宫内膜息肉 | F4: 1433
A5: see_meta | B5: foshan_6 | C5: Foshan | D5: 最终诊断::瘢痕妊娠 | E5: 妊娠相关 | F5: 1322
A6: see_meta | B6: foshan_7 | C6: Foshan | D6: 最终诊断::1.剖宫产后子宫瘢痕妊娠IIb型 | E6: 妊娠相关 | F6: 1808
A7: see_meta | B7: foshan_8 | C7: Foshan | D7: 最终诊断::1.子宫瘢痕妊娠IIa型 | E7: 妊娠相关 | F7: 1090
A8: see_meta | B8: foshan_9 | C8: Foshan | D8: 最终诊断::1.疤痕妊娠 | E8: 妊娠相关 | F8: 2001
A9: see_meta | B9: foshan_10 | C9: Foshan | D9: 最终诊断::1.高-中分化子宫内膜样癌IIIA1期（T3N0M0） | E9: 恶性肿瘤 | F9: 3280
A10: see_meta | B10: foshan_11 | C10: Foshan | D10: 最终诊断::低分化子宫内膜样腺癌IIIC1期 | E10: 恶性肿瘤 | F10: 2269
A11: see_meta | B11: foshan_12 | C11: Foshan | D11: 最终诊断::1.宫颈腺样囊性癌IB2期（T1b2N0M0） | E11: 恶性肿瘤 | F11: 2894
A12: see_meta | B12: foshan_13 | C12: Foshan | D12: 最终诊断::1.宫颈低分化腺癌IB3期（T1N0MO） 2.乳腺癌 | E12: 恶性肿瘤 | F12: 3203
A13: see_meta | B13: foshan_14 | C13: Foshan | D13: 最终诊断::宫颈中低分化透明细胞腺癌 IIA1期（T2a1N0M0） | E13: 恶性肿瘤 | F13: 2980
... A305: see_meta | B305: wuhan_104 | C305: Wuhan | D305: 最终诊断:子宫内膜息肉；轻度贫血 | E305: 子宫内膜息肉 | F305: 856

Sheet 明细_icd
A1: source_table | B1: ICD10Code | C1: ICD10Name | D1: Cases
A2: analysis_viz/data/derived/figdata/v2_subplots/G1_dataset/G1_llm_case_taxonomy_v1.csv[final_icd10_code] | B2: N84.0 | C2: 子宫内膜息肉 | D2: 57
A3: analysis_viz/data/derived/figdata/v2_subplots/G1_dataset/G1_llm_case_taxonomy_v1.csv[final_icd10_code] | B3: N84.0 | C3: 子宫体息肉 | D3: 21
A4: analysis_viz/data/derived/figdata/v2_subplots/G1_dataset/G1_llm_case_taxonomy_v1.csv[final_icd10_code] | B4: C54.1 | C4: 子宫内膜恶性肿瘤 | D4: 19
A5: analysis_viz/data/derived/figdata/v2_subplots/G1_dataset/G1_llm_case_taxonomy_v1.csv[final_icd10_code] | B5: C53.9 | C5: 宫颈恶性肿瘤 | D5: 17
A6: analysis_viz/data/derived/figdata/v2_subplots/G1_dataset/G1_llm_case_taxonomy_v1.csv[final_icd10_code] | B6: N80.0 | C6: 子宫腺肌病 | D6: 10
A7: analysis_viz/data/derived/figdata/v2_subplots/G1_dataset/G1_llm_case_taxonomy_v1.csv[final_icd10_code] | B7: C53.9 | C7: 子宫颈恶性肿瘤 | D7: 9
A8: analysis_viz/data/derived/figdata/v2_subplots/G1_dataset/G1_llm_case_taxonomy_v1.csv[final_icd10_code] | B8: D25.0 | C8: 子宫黏膜下平滑肌瘤 | D8: 7
A9: analysis_viz/data/derived/figdata/v2_subplots/G1_dataset/G1_llm_case_taxonomy_v1.csv[final_icd10_code] | B9: D25.0 | C9: 子宫粘膜下平滑肌瘤 | D9: 6
A10: analysis_viz/data/derived/figdata/v2_subplots/G1_dataset/G1_llm_case_taxonomy_v1.csv[final_icd10_code] | B10: O00.1 | C10: 输卵管妊娠 | D10: 6
A11: analysis_viz/data/derived/figdata/v2_subplots/G1_dataset/G1_llm_case_taxonomy_v1.csv[final_icd10_code] | B11: O20.0 | C11: 先兆流产 | D11: 6
A12: analysis_viz/data/derived/figdata/v2_subplots/G1_dataset/G1_llm_case_taxonomy_v1.csv[final_icd10_code] | B12: N71.9 | C12: 子宫内膜炎 | D12: 5
A13: analysis_viz/data/derived/figdata/v2_subplots/G1_dataset/G1_llm_case_taxonomy_v1.csv[final_icd10_code] | B13: N84.1 | C13: 宫颈息肉 | D13: 5
... A97: analysis_viz/data/derived/figdata/v2_subplots/G1_dataset/G1_llm_case_taxonomy_v1.csv[final_icd10_code] | B97: T83.3 | C97: 宫内节育器的机械性并发症 | D97: 1

Sheet 明细_icd_病例
A1: source_table | B1: center | C1: case_id | D1: final_icd10_code | E1: final_icd10_name | F1: source_gt_path | G1: ICD10Chapter | H1: ICD10ChapterName
A2: analysis_viz/data/derived/figdata/v2_subplots/G1_dataset/G1_llm_case_taxonomy_v1.csv[center,case_id,final_icd10_code] | B2: 佛山 | C2: foshan_10 | D2: C54.1 | E2: 子宫内膜恶性肿瘤 | F2: analysis_viz/data/raw/center_data/佛山/GT/standardized_foshan.xlsx | G2: C00-D48 | H2: Neoplasms
A3: analysis_viz/data/derived/figdata/v2_subplots/G1_dataset/G1_llm_case_taxonomy_v1.csv[center,case_id,final_icd10_code] | B3: 佛山 | C3: foshan_100 | D3: D25.9 | E3: 子宫平滑肌瘤,未特指 | F3: analysis_viz/data/raw/center_data/佛山/GT/standardized_foshan.xlsx | G3: C00-D48 | H3: Neoplasms
A4: analysis_viz/data/derived/figdata/v2_subplots/G1_dataset/G1_llm_case_taxonomy_v1.csv[center,case_id,final_icd10_code] | B4: 佛山 | C4: foshan_101 | D4: C54.1 | E4: 子宫内膜恶性肿瘤 | F4: analysis_viz/data/raw/center_data/佛山/GT/standardized_foshan.xlsx | G4: C00-D48 | H4: Neoplasms
A5: analysis_viz/data/derived/figdata/v2_subplots/G1_dataset/G1_llm_case_taxonomy_v1.csv[center,case_id,final_icd10_code] | B5: 佛山 | C5: foshan_102 | D5: N85.1 | E5: 子宫内膜腺体性增生 | F5: analysis_viz/data/raw/center_data/佛山/GT/standardized_foshan.xlsx | G5: N00-N99 | H5: Diseases of the genitourinary system
A6: analysis_viz/data/derived/figdata/v2_subplots/G1_dataset/G1_llm_case_taxonomy_v1.csv[center,case_id,final_icd10_code] | B6: 佛山 | C6: foshan_103 | D6: N85.0 | E6: 子宫内膜腺性增生 | F6: analysis_viz/data/raw/center_data/佛山/GT/standardized_foshan.xlsx | G6: N00-N99 | H6: Diseases of the genitourinary system
A7: analysis_viz/data/derived/figdata/v2_subplots/G1_dataset/G1_llm_case_taxonomy_v1.csv[center,case_id,final_icd10_code] | B7: 佛山 | C7: foshan_104 | D7: C54.1 | E7: 子宫内膜恶性肿瘤 | F7: analysis_viz/data/raw/center_data/佛山/GT/standardized_foshan.xlsx | G7: C00-D48 | H7: Neoplasms
A8: analysis_viz/data/derived/figdata/v2_subplots/G1_dataset/G1_llm_case_taxonomy_v1.csv[center,case_id,final_icd10_code] | B8: 佛山 | C8: foshan_105 | D8: N87.1 | E8: 宫颈中度不典型增生 | F8: analysis_viz/data/raw/center_data/佛山/GT/standardized_foshan.xlsx | G8: N00-N99 | H8: Diseases of the genitourinary system
A9: analysis_viz/data/derived/figdata/v2_subplots/G1_dataset/G1_llm_case_taxonomy_v1.csv[center,case_id,final_icd10_code] | B9: 佛山 | C9: foshan_106 | D9: D25.9 | E9: 子宫平滑肌瘤，未特指 | F9: analysis_viz/data/raw/center_data/佛山/GT/standardized_foshan.xlsx | G9: C00-D48 | H9: Neoplasms
A10: analysis_viz/data/derived/figdata/v2_subplots/G1_dataset/G1_llm_case_taxonomy_v1.csv[center,case_id,final_icd10_code] | B10: 佛山 | C10: foshan_107 | D10: N84.1 | E10: 宫颈息肉 | F10: analysis_viz/data/raw/center_data/佛山/GT/standardized_foshan.xlsx | G10: N00-N99 | H10: Diseases of the genitourinary system
A11: analysis_viz/data/derived/figdata/v2_subplots/G1_dataset/G1_llm_case_taxonomy_v1.csv[center,case_id,final_icd10_code] | B11: 佛山 | C11: foshan_108 | D11: N84.1 | E11: 宫颈息肉 | F11: analysis_viz/data/raw/center_data/佛山/GT/standardized_foshan.xlsx | G11: N00-N99 | H11: Diseases of the genitourinary system
A12: analysis_viz/data/derived/figdata/v2_subplots/G1_dataset/G1_llm_case_taxonomy_v1.csv[center,case_id,final_icd10_code] | B12: 佛山 | C12: foshan_109 | D12: N84.0 | E12: 子宫内膜息肉 | F12: analysis_viz/data/raw/center_data/佛山/GT/standardized_foshan.xlsx | G12: N00-N99 | H12: Diseases of the genitourinary system
... A305: analysis_viz/data/derived/figdata/v2_subplots/G1_dataset/G1_llm_case_taxonomy_v1.csv[center,case_id,final_icd10_code] | B305: 武汉 | C305: wuhan_99 | D305: N84.0 | E305: 子宫体息肉 | F305: analysis_viz/data/raw/center_data/武汉/GT/standardized_wuhan - 移动信息.xlsx | G305: N00-N99 | H305: Diseases of the genitourinary system

Sheet 明细_longtail
A1: source_table | B1: palm_coein | C1: cases | D1: rank
A2: 由 detail_diag_stage_palm 中 D3 最终阶段按 palm_coein 汇总；仅对应当前保留的 PALM-COEIN 长尾子图。 | B2: M-恶性/增生 | C2: 95 | D2: 1
A3: 由 detail_diag_stage_palm 中 D3 最终阶段按 palm_coein 汇总；仅对应当前保留的 PALM-COEIN 长尾子图。 | B3: P-息肉 | C3: 94 | D3: 2
A4: 由 detail_diag_stage_palm 中 D3 最终阶段按 palm_coein 汇总；仅对应当前保留的 PALM-COEIN 长尾子图。 | B4: 不适用 | C4: 35 | D4: 3
A5: 由 detail_diag_stage_palm 中 D3 最终阶段按 palm_coein 汇总；仅对应当前保留的 PALM-COEIN 长尾子图。 | B5: L-肌瘤 | C5: 32 | D5: 4
A6: 由 detail_diag_stage_palm 中 D3 最终阶段按 palm_coein 汇总；仅对应当前保留的 PALM-COEIN 长尾子图。 | B6: A-腺肌症 | C6: 13 | D6: 5
A7: 由 detail_diag_stage_palm 中 D3 最终阶段按 palm_coein 汇总；仅对应当前保留的 PALM-COEIN 长尾子图。 | B7: E-子宫内膜原因 | C7: 12 | D7: 6
A8: 由 detail_diag_stage_palm 中 D3 最终阶段按 palm_coein 汇总；仅对应当前保留的 PALM-COEIN 长尾子图。 | B8: N-非肿瘤 | C8: 12 | D8: 7
A9: 由 detail_diag_stage_palm 中 D3 最终阶段按 palm_coein 汇总；仅对应当前保留的 PALM-COEIN 长尾子图。 | B9: O-排卵障碍 | C9: 7 | D9: 8
A10: 由 detail_diag_stage_palm 中 D3 最终阶段按 palm_coein 汇总；仅对应当前保留的 PALM-COEIN 长尾子图。 | B10: I-医源性 | C10: 4 | D10: 9

Sheet 明细_检查_type
A1: source_table | B1: Stage | C1: Category | D1: Cases
A2: see_meta | B2: Outpatient | C2: 实验室检查 | D2: 190
A3: see_meta | B3: Outpatient | C3: 影像学检查 | D3: 250
A4: see_meta | B4: Outpatient | C4: 内镜检查 | D4: 14
A5: see_meta | B5: Outpatient | C5: 病理学检查 | D5: 21
A6: see_meta | B6: Outpatient | C6: 其他检查 | D6: 10
A7: see_meta | B7: Admission | C7: 实验室检查 | D7: 283
A8: see_meta | B8: Admission | C8: 影像学检查 | D8: 144
A9: see_meta | B9: Admission | C9: 内镜检查 | D9: 211
A10: see_meta | B10: Admission | C10: 病理学检查 | D10: 75
A11: see_meta | B11: Admission | C11: 其他检查 | D11: 80

Sheet 明细_检查_type_病例_level
A1: source_table | B1: center | C1: case_id | D1: Stage | E1: Category | F1: segment_text | G1: is_counted | H1: source_sheet | I1: source_column | J1: source_path | K1: count_rule
A2: analysis_viz/data/raw/center_data/*/GT/*.xlsx:Sheet1[GT_Outpatient_Checks,GT_Admission_Checks] | B2: 佛山 | C2: foshan_3 | D2: Outpatient | E2: 实验室检查 | G2: 0 | H2: standardized_foshan.xlsx:Sheet1 | I2: GT_Outpatient_Checks | J2: analysis_viz/data/raw/center_data/佛山/GT/standardized_foshan.xlsx | K2: 按文本关键词命中类型；若片段非无且未命中则归其他检查
A3: analysis_viz/data/raw/center_data/*/GT/*.xlsx:Sheet1[GT_Outpatient_Checks,GT_Admission_Checks] | B3: 佛山 | C3: foshan_3 | D3: Outpatient | E3: 影像学检查 | F3: 检查 | G3: 1 | H3: standardized_foshan.xlsx:Sheet1 | I3: GT_Outpatient_Checks | J3: analysis_viz/data/raw/center_data/佛山/GT/standardized_foshan.xlsx | K3: 按文本关键词命中类型；若片段非无且未命中则归其他检查
A4: analysis_viz/data/raw/center_data/*/GT/*.xlsx:Sheet1[GT_Outpatient_Checks,GT_Admission_Checks] | B4: 佛山 | C4: foshan_3 | D4: Outpatient | E4: 内镜检查 | G4: 0 | H4: standardized_foshan.xlsx:Sheet1 | I4: GT_Outpatient_Checks | J4: analysis_viz/data/raw/center_data/佛山/GT/standardized_foshan.xlsx | K4: 按文本关键词命中类型；若片段非无且未命中则归其他检查
A5: analysis_viz/data/raw/center_data/*/GT/*.xlsx:Sheet1[GT_Outpatient_Checks,GT_Admission_Checks] | B5: 佛山 | C5: foshan_3 | D5: Outpatient | E5: 病理学检查 | G5: 0 | H5: standardized_foshan.xlsx:Sheet1 | I5: GT_Outpatient_Checks | J5: analysis_viz/data/raw/center_data/佛山/GT/standardized_foshan.xlsx | K5: 按文本关键词命中类型；若片段非无且未命中则归其他检查
A6: analysis_viz/data/raw/center_data/*/GT/*.xlsx:Sheet1[GT_Outpatient_Checks,GT_Admission_Checks] | B6: 佛山 | C6: foshan_3 | D6: Outpatient | E6: 其他检查 | G6: 0 | H6: standardized_foshan.xlsx:Sheet1 | I6: GT_Outpatient_Checks | J6: analysis_viz/data/raw/center_data/佛山/GT/standardized_foshan.xlsx | K6: 按文本关键词命中类型；若片段非无且未命中则归其他检查
A7: analysis_viz/data/raw/center_data/*/GT/*.xlsx:Sheet1[GT_Outpatient_Checks,GT_Admission_Checks] | B7: 佛山 | C7: foshan_3 | D7: Admission | E7: 实验室检查 | F7: 血常规、凝血四项、肝肾功能、免疫三项、乙肝五项、电解质、HPV、TCT等未见异常。 ; | G7: 1 | H7: standardized_foshan.xlsx:Sheet1 | I7: GT_Admission_Checks | J7: analysis_viz/data/raw/center_data/佛山/GT/standardized_foshan.xlsx | K7: segment_exists && segment_not_none
A8: analysis_viz/data/raw/center_data/*/GT/*.xlsx:Sheet1[GT_Outpatient_Checks,GT_Admission_Checks] | B8: 佛山 | C8: foshan_3 | D8: Admission | E8: 影像学检查 | F8: 无 ; | G8: 0 | H8: standardized_foshan.xlsx:Sheet1 | I8: GT_Admission_Checks | J8: analysis_viz/data/raw/center_data/佛山/GT/standardized_foshan.xlsx | K8: segment_exists && segment_not_none
A9: analysis_viz/data/raw/center_data/*/GT/*.xlsx:Sheet1[GT_Outpatient_Checks,GT_Admission_Checks] | B9: 佛山 | C9: foshan_3 | D9: Admission | E9: 内镜检查 | F9: 无 ; | G9: 0 | H9: standardized_foshan.xlsx:Sheet1 | I9: GT_Admission_Checks | J9: analysis_viz/data/raw/center_data/佛山/GT/standardized_foshan.xlsx | K9: segment_exists && segment_not_none
A10: analysis_viz/data/raw/center_data/*/GT/*.xlsx:Sheet1[GT_Outpatient_Checks,GT_Admission_Checks] | B10: 佛山 | C10: foshan_3 | D10: Admission | E10: 病理学检查 | F10: 无 ; | G10: 0 | H10: standardized_foshan.xlsx:Sheet1 | I10: GT_Admission_Checks | J10: analysis_viz/data/raw/center_data/佛山/GT/standardized_foshan.xlsx | K10: segment_exists && segment_not_none
A11: analysis_viz/data/raw/center_data/*/GT/*.xlsx:Sheet1[GT_Outpatient_Checks,GT_Admission_Checks] | B11: 佛山 | C11: foshan_3 | D11: Admission | E11: 其他检查 | F11: 心电图未见明显异常。 | G11: 1 | H11: standardized_foshan.xlsx:Sheet1 | I11: GT_Admission_Checks | J11: analysis_viz/data/raw/center_data/佛山/GT/standardized_foshan.xlsx | K11: segment_exists && segment_not_none
A12: analysis_viz/data/raw/center_data/*/GT/*.xlsx:Sheet1[GT_Outpatient_Checks,GT_Admission_Checks] | B12: 佛山 | C12: foshan_4 | D12: Outpatient | E12: 实验室检查 | G12: 0 | H12: standardized_foshan.xlsx:Sheet1 | I12: GT_Outpatient_Checks | J12: analysis_viz/data/raw/center_data/佛山/GT/standardized_foshan.xlsx | K12: 按文本关键词命中类型；若片段非无且未命中则归其他检查
A13: analysis_viz/data/raw/center_data/*/GT/*.xlsx:Sheet1[GT_Outpatient_Checks,GT_Admission_Checks] | B13: 佛山 | C13: foshan_4 | D13: Outpatient | E13: 影像学检查 | G13: 0 | H13: standardized_foshan.xlsx:Sheet1 | I13: GT_Outpatient_Checks | J13: analysis_viz/data/raw/center_data/佛山/GT/standardized_foshan.xlsx | K13: 按文本关键词命中类型；若片段非无且未命中则归其他检查
A14: analysis_viz/data/raw/center_data/*/GT/*.xlsx:Sheet1[GT_Outpatient_Checks,GT_Admission_Checks] | B14: 佛山 | C14: foshan_4 | D14: Outpatient | E14: 内镜检查 | G14: 0 | H14: standardized_foshan.xlsx:Sheet1 | I14: GT_Outpatient_Checks | J14: analysis_viz/data/raw/center_data/佛山/GT/standardized_foshan.xlsx | K14: 按文本关键词命中类型；若片段非无且未命中则归其他检查
A15: analysis_viz/data/raw/center_data/*/GT/*.xlsx:Sheet1[GT_Outpatient_Checks,GT_Admission_Checks] | B15: 佛山 | C15: foshan_4 | D15: Outpatient | E15: 病理学检查 | G15: 0 | H15: standardized_foshan.xlsx:Sheet1 | I15: GT_Outpatient_Checks | J15: analysis_viz/data/raw/center_data/佛山/GT/standardized_foshan.xlsx | K15: 按文本关键词命中类型；若片段非无且未命中则归其他检查
A16: analysis_viz/data/raw/center_data/*/GT/*.xlsx:Sheet1[GT_Outpatient_Checks,GT_Admission_Checks] | B16: 佛山 | C16: foshan_4 | D16: Outpatient | E16: 其他检查 | G16: 0 | H16: standardized_foshan.xlsx:Sheet1 | I16: GT_Outpatient_Checks | J16: analysis_viz/data/raw/center_data/佛山/GT/standardized_foshan.xlsx | K16: 按文本关键词命中类型；若片段非无且未命中则归其他检查
A17: analysis_viz/data/raw/center_data/*/GT/*.xlsx:Sheet1[GT_Outpatient_Checks,GT_Admission_Checks] | B17: 佛山 | C17: foshan_4 | D17: Admission | E17: 实验室检查 | F17: 血型：A型，RHD阳性。HCG（-）。白带常规、血常规、凝血四项、D-二聚体、乙肝表面抗原定量、免疫三项、CEA、CA_125、HE4、绝经前ROMA值、绝经后ROMA值、CA_199、SCC、生理激素六项、肝肾功、电解质未见明显异常。HPV、TCT阴性。 ; | G17: 1 | H17: standardized_foshan.xlsx:Sheet1 | I17: GT_Admission_Checks | J17: analysis_viz/data/raw/center_data/佛山/GT/standardized_foshan.xlsx | K17: segment_exists && segment_not_none
A18: analysis_viz/data/raw/center_data/*/GT/*.xlsx:Sheet1[GT_Outpatient_Checks,GT_Admission_Checks] | B18: 佛山 | C18: foshan_4 | D18: Admission | E18: 影像学检查 | F18: DR胸部正侧位片：心、肺、膈未见明确异常。彩超：肝、胆、脾、胰、双肾、膀胱未见明显异常。 ; | G18: 1 | H18: standardized_foshan.xlsx:Sheet1 | I18: GT_Admission_Checks | J18: analysis_viz/data/raw/center_data/佛山/GT/standardized_foshan.xlsx | K18: segment_exists && segment_not_none
A19: analysis_viz/data/raw/center_data/*/GT/*.xlsx:Sheet1[GT_Outpatient_Checks,GT_Admission_Checks] | B19: 佛山 | C19: foshan_4 | D19: Admission | E19: 内镜检查 | F19: 无 ; | G19: 0 | H19: standardized_foshan.xlsx:Sheet1 | I19: GT_Admission_Checks | J19: analysis_viz/data/raw/center_data/佛山/GT/standardized_foshan.xlsx | K19: segment_exists && segment_not_none
A20: analysis_viz/data/raw/center_data/*/GT/*.xlsx:Sheet1[GT_Outpatient_Checks,GT_Admission_Checks] | B20: 佛山 | C20: foshan_4 | D20: Admission | E20: 病理学检查 | F20: 无 ; | G20: 0 | H20: standardized_foshan.xlsx:Sheet1 | I20: GT_Admission_Checks | J20: analysis_viz/data/raw/center_data/佛山/GT/standardized_foshan.xlsx | K20: segment_exists && segment_not_none
A21: analysis_viz/data/raw/center_data/*/GT/*.xlsx:Sheet1[GT_Outpatient_Checks,GT_Admission_Checks] | B21: 佛山 | C21: foshan_4 | D21: Admission | E21: 其他检查 | F21: 心电图未见明显异常。 | G21: 1 | H21: standardized_foshan.xlsx:Sheet1 | I21: GT_Admission_Checks | J21: analysis_viz/data/raw/center_data/佛山/GT/standardized_foshan.xlsx | K21: segment_exists && segment_not_none
A22: analysis_viz/data/raw/center_data/*/GT/*.xlsx:Sheet1[GT_Outpatient_Checks,GT_Admission_Checks] | B22: 佛山 | C22: foshan_5 | D22: Outpatient | E22: 实验室检查 | F22: 检验 | G22: 1 | H22: standardized_foshan.xlsx:Sheet1 | I22: GT_Outpatient_Checks | J22: analysis_viz/data/raw/center_data/佛山/GT/standardized_foshan.xlsx | K22: 按文本关键词命中类型；若片段非无且未命中则归其他检查
A23: analysis_viz/data/raw/center_data/*/GT/*.xlsx:Sheet1[GT_Outpatient_Checks,GT_Admission_Checks] | B23: 佛山 | C23: foshan_5 | D23: Outpatient | E23: 影像学检查 | F23: 检查、检验 | G23: 1 | H23: standardized_foshan.xlsx:Sheet1 | I23: GT_Outpatient_Checks | J23: analysis_viz/data/raw/center_data/佛山/GT/standardized_foshan.xlsx | K23: 按文本关键词命中类型；若片段非无且未命中则归其他检查
A24: analysis_viz/data/raw/center_data/*/GT/*.xlsx:Sheet1[GT_Outpatient_Checks,GT_Admission_Checks] | B24: 佛山 | C24: foshan_5 | D24: Outpatient | E24: 内镜检查 | G24: 0 | H24: standardized_foshan.xlsx:Sheet1 | I24: GT_Outpatient_Checks | J24: analysis_viz/data/raw/center_data/佛山/GT/standardized_foshan.xlsx | K24: 按文本关键词命中类型；若片段非无且未命中则归其他检查
A25: analysis_viz/data/raw/center_data/*/GT/*.xlsx:Sheet1[GT_Outpatient_Checks,GT_Admission_Checks] | B25: 佛山 | C25: foshan_5 | D25: Outpatient | E25: 病理学检查 | G25: 0 | H25: standardized_foshan.xlsx:Sheet1 | I25: GT_Outpatient_Checks | J25: analysis_viz/data/raw/center_data/佛山/GT/standardized_foshan.xlsx | K25: 按文本关键词命中类型；若片段非无且未命中则归其他检查
A26: analysis_viz/data/raw/center_data/*/GT/*.xlsx:Sheet1[GT_Outpatient_Checks,GT_Admission_Checks] | B26: 佛山 | C26: foshan_5 | D26: Outpatient | E26: 其他检查 | G26: 0 | H26: standardized_foshan.xlsx:Sheet1 | I26: GT_Outpatient_Checks | J26: analysis_viz/data/raw/center_data/佛山/GT/standardized_foshan.xlsx | K26: 按文本关键词命中类型；若片段非无且未命中则归其他检查
A27: analysis_viz/data/raw/center_data/*/GT/*.xlsx:Sheet1[GT_Outpatient_Checks,GT_Admission_Checks] | B27: 佛山 | C27: foshan_5 | D27: Admission | E27: 实验室检查 | F27: 血型：O型RHD阳性。HCG（-）。绝经前ROMA值70.7128％，绝经后ROMA值44.5737％。尿检测全套：尿蛋白+-，尿亚硝酸盐2+，尿潜血3+，尿白细胞酯酶+-，尿沉渣红细胞79.0/ul。血常规、凝血四项、D-二聚体、CA_125、HE4、CA_199、乙肝表面抗原定量、免疫三项、肝肾功、大便常规未见明显异常。 ; | G27: 1 | H27: standardized_foshan.xlsx:Sheet1 | I27: GT_Admission_Checks | J27: analysis_viz/data/raw/center_data/佛山/GT/standardized_foshan.xlsx | K27: segment_exists && segment_not_none
A28: analysis_viz/data/raw/center_data/*/GT/*.xlsx:Sheet1[GT_Outpatient_Checks,GT_Admission_Checks] | B28: 佛山 | C28: foshan_5 | D28: Admission | E28: 影像学检查 | F28: DR胸部正侧位片：心、肺、膈未见明确异常。彩超子宫附件(经腹经阴道）(2023-05-23)：1、左附件区液性包块（3.0cm×2.5cm×3.0）； 2、符合宫颈纳氏囊肿声像；3、盆腔积液（2.0cm）；4、右附件未见明显异常；5、子宫腔内节育器位置未见异常。 ; | G28: 1 | H28: standardized_foshan.xlsx:Sheet1 | I28: GT_Admission_Checks | J28: analysis_viz/data/raw/center_data/佛山/GT/standardized_foshan.xlsx | K28: segment_exists && segment_not_none
A29: analysis_viz/data/raw/center_data/*/GT/*.xlsx:Sheet1[GT_Outpatient_Checks,GT_Admission_Checks] | B29: 佛山 | C29: foshan_5 | D29: Admission | E29: 内镜检查 | F29: 无 ; | G29: 0 | H29: standardized_foshan.xlsx:Sheet1 | I29: GT_Admission_Checks | J29: analysis_viz/data/raw/center_data/佛山/GT/standardized_foshan.xlsx | K29: segment_exists && segment_not_none
A30: analysis_viz/data/raw/center_data/*/GT/*.xlsx:Sheet1[GT_Outpatient_Checks,GT_Admission_Checks] | B30: 佛山 | C30: foshan_5 | D30: Admission | E30: 病理学检查 | F30: 无 ; | G30: 0 | H30: standardized_foshan.xlsx:Sheet1 | I30: GT_Admission_Checks | J30: analysis_viz/data/raw/center_data/佛山/GT/standardized_foshan.xlsx | K30: segment_exists && segment_not_none
A31: analysis_viz/data/raw/center_data/*/GT/*.xlsx:Sheet1[GT_Outpatient_Checks,GT_Admission_Checks] | B31: 佛山 | C31: foshan_5 | D31: Admission | E31: 其他检查 | F31: 科内床旁心电图(2023-05-23)：心脏沿其长轴逆钟向转位；Tv2＞Tv6图形改变。 | G31: 1 | H31: standardized_foshan.xlsx:Sheet1 | I31: GT_Admission_Checks | J31: analysis_viz/data/raw/center_data/佛山/GT/standardized_foshan.xlsx | K31: segment_exists && segment_not_none
A32: analysis_viz/data/raw/center_data/*/GT/*.xlsx:Sheet1[GT_Outpatient_Checks,GT_Admission_Checks] | B32: 佛山 | C32: foshan_6 | D32: Outpatient | E32: 实验室检查 | F32: 检验 | G32: 1 | H32: standardized_foshan.xlsx:Sheet1 | I32: GT_Outpatient_Checks | J32: analysis_viz/data/raw/center_data/佛山/GT/standardized_foshan.xlsx | K32: 按文本关键词命中类型；若片段非无且未命中则归其他检查
A33: analysis_viz/data/raw/center_data/*/GT/*.xlsx:Sheet1[GT_Outpatient_Checks,GT_Admission_Checks] | B33: 佛山 | C33: foshan_6 | D33: Outpatient | E33: 影像学检查 | F33: 检查 | G33: 1 | H33: standardized_foshan.xlsx:Sheet1 | I33: GT_Outpatient_Checks | J33: analysis_viz/data/raw/center_data/佛山/GT/standardized_foshan.xlsx | K33: 按文本关键词命中类型；若片段非无且未命中则归其他检查
A34: analysis_viz/data/raw/center_data/*/GT/*.xlsx:Sheet1[GT_Outpatient_Checks,GT_Admission_Checks] | B34: 佛山 | C34: foshan_6 | D34: Outpatient | E34: 内镜检查 | G34: 0 | H34: standardized_foshan.xlsx:Sheet1 | I34: GT_Outpatient_Checks | J34: analysis_viz/data/raw/center_data/佛山/GT/standardized_foshan.xlsx | K34: 按文本关键词命中类型；若片段非无且未命中则归其他检查
A35: analysis_viz/data/raw/center_data/*/GT/*.xlsx:Sheet1[GT_Outpatient_Checks,GT_Admission_Checks] | B35: 佛山 | C35: foshan_6 | D35: Outpatient | E35: 病理学检查 | G35: 0 | H35: standardized_foshan.xlsx:Sheet1 | I35: GT_Outpatient_Checks | J35: analysis_viz/data/raw/center_data/佛山/GT/standardized_foshan.xlsx | K35: 按文本关键词命中类型；若片段非无且未命中则归其他检查
A36: analysis_viz/data/raw/center_data/*/GT/*.xlsx:Sheet1[GT_Outpatient_Checks,GT_Admission_Checks] | B36: 佛山 | C36: foshan_6 | D36: Outpatient | E36: 其他检查 | G36: 0 | H36: standardized_foshan.xlsx:Sheet1 | I36: GT_Outpatient_Checks | J36: analysis_viz/data/raw/center_data/佛山/GT/standardized_foshan.xlsx | K36: 按文本关键词命中类型；若片段非无且未命中则归其他检查
A37: analysis_viz/data/raw/center_data/*/GT/*.xlsx:Sheet1[GT_Outpatient_Checks,GT_Admission_Checks] | B37: 佛山 | C37: foshan_6 | D37: Admission | E37: 实验室检查 | F37: 血常规(2025-04-10)：单核细胞绝对值0.63*10^9/L，中性粒细胞总数6.39*10^9/L，中性粒与淋巴细胞比值3.54。血型鉴定(2025-04-10)：ABO血型O型， RH(D)血型阳性。肝功1(2025-04-10)：谷氨酰转肽酶56U/L，总蛋白67.7g/L。 乙肝五项(CLIA)(2025-04-10)：乙肝表面抗体定量625.32mIU/mL，乙肝e抗体半定量1.98PEIU/mL，乙肝核心抗体半定量>45.00PEIU/mL。尿液分析、凝血四项、免疫三项、肾功、电解质六项未见异常。 ; | G37: 1 | H37: standardized_foshan.xlsx:Sheet1 | I37: GT_Admission_Checks | J37: analysis_viz/data/raw/center_data/佛山/GT/standardized_foshan.xlsx | K37: segment_exists && segment_not_none
A38: analysis_viz/data/raw/center_data/*/GT/*.xlsx:Sheet1[GT_Outpatient_Checks,GT_Admission_Checks] | B38: 佛山 | C38: foshan_6 | D38: Admission | E38: 影像学检查 | F38: 彩超子宫附件(经腹经阴道）(2025-04-10)：1、符合宫内孕6周+，活胎，宫腔内见一孕囊样回声，大小为4.3x1.1x3.6cm，形态不规则，呈长条状充满宫腔，内可见卵黄囊及胚芽0.4cm； 2、宫腔粘连；3、子宫内膜强回声斑：考虑钙化灶；4、盆腔积液；5、双附件未见明显异常。 ; | G38: 1 | H38: standardized_foshan.xlsx:Sheet1 | I38: GT_Admission_Checks | J38: analysis_viz/data/raw/center_data/佛山/GT/standardized_foshan.xlsx | K38: segment_exists && segment_not_none
A39: analysis_viz/data/raw/center_data/*/GT/*.xlsx:Sheet1[GT_Outpatient_Checks,GT_Admission_Checks] | B39: 佛山 | C39: foshan_6 | D39: Admission | E39: 内镜检查 | F39: 无 ; | G39: 0 | H39: standardized_foshan.xlsx:Sheet1 | I39: GT_Admission_Checks | J39: analysis_viz/data/raw/center_data/佛山/GT/standardized_foshan.xlsx | K39: segment_exists && segment_not_none
A40: analysis_viz/data/raw/center_data/*/GT/*.xlsx:Sheet1[GT_Outpatient_Checks,GT_Admission_Checks] | B40: 佛山 | C40: foshan_6 | D40: Admission | E40: 病理学检查 | F40: 无 ; | G40: 0 | H40: standardized_foshan.xlsx:Sheet1 | I40: GT_Admission_Checks | J40: analysis_viz/data/raw/center_data/佛山/GT/standardized_foshan.xlsx | K40: segment_exists && segment_not_none
...

Sheet 明细_方案_type
A1: source_table | B1: Stage | C1: Category | D1: Cases
A2: see_meta | B2: Rehab_Plan | C2: 其他 | D2: 448
A3: see_meta | B3: Followup_Plan | C3: 随访/复查 | D3: 398
A4: see_meta | B4: PostOp_Plan | C4: 手术 | D4: 317
A5: see_meta | B5: Surgery_Plan | C5: 手术 | D5: 294
A6: see_meta | B6: Rehab_Plan | C6: 康复/护理 | D6: 219
A7: see_meta | B7: Followup_Plan | C7: 其他 | D7: 124
A8: see_meta | B8: PostOp_Plan | C8: 其他 | D8: 93
A9: see_meta | B9: Rehab_Plan | C9: 随访/复查 | D9: 92
A10: see_meta | B10: Followup_Plan | C10: 手术 | D10: 59
A11: see_meta | B11: Surgery_Plan | C11: 其他 | D11: 53
A12: see_meta | B12: PostOp_Plan | C12: 内分泌/激素 | D12: 22
A13: see_meta | B13: Surgery_Plan | C13: 化疗 | D13: 12
... A27: see_meta | B27: Surgery_Plan | C27: 内分泌/激素 | D27: 1

Sheet 明细_方案_continuity
A1: source_table | B1: center | C1: case_id | D1: plan_label | E1: source_gt_path | F1: plan_stage
A2: analysis_viz/data/derived/figdata/v2_subplots/G1_dataset/G1_llm_case_taxonomy_v1.csv | B2: 佛山 | C2: foshan_10 | D2: 手术处置 | E2: analysis_viz/data/raw/center_data/佛山/GT/standardized_foshan.xlsx | F2: Surgery
A3: analysis_viz/data/derived/figdata/v2_subplots/G1_dataset/G1_llm_case_taxonomy_v1.csv | B3: 佛山 | C3: foshan_100 | D3: 手术处置 | E3: analysis_viz/data/raw/center_data/佛山/GT/standardized_foshan.xlsx | F3: Surgery
A4: analysis_viz/data/derived/figdata/v2_subplots/G1_dataset/G1_llm_case_taxonomy_v1.csv | B4: 佛山 | C4: foshan_101 | D4: 手术处置 | E4: analysis_viz/data/raw/center_data/佛山/GT/standardized_foshan.xlsx | F4: Surgery
A5: analysis_viz/data/derived/figdata/v2_subplots/G1_dataset/G1_llm_case_taxonomy_v1.csv | B5: 佛山 | C5: foshan_102 | D5: 手术处置 | E5: analysis_viz/data/raw/center_data/佛山/GT/standardized_foshan.xlsx | F5: Surgery
A6: analysis_viz/data/derived/figdata/v2_subplots/G1_dataset/G1_llm_case_taxonomy_v1.csv | B6: 佛山 | C6: foshan_103 | D6: 手术处置 | E6: analysis_viz/data/raw/center_data/佛山/GT/standardized_foshan.xlsx | F6: Surgery
A7: analysis_viz/data/derived/figdata/v2_subplots/G1_dataset/G1_llm_case_taxonomy_v1.csv | B7: 佛山 | C7: foshan_104 | D7: 手术处置 | E7: analysis_viz/data/raw/center_data/佛山/GT/standardized_foshan.xlsx | F7: Surgery
A8: analysis_viz/data/derived/figdata/v2_subplots/G1_dataset/G1_llm_case_taxonomy_v1.csv | B8: 佛山 | C8: foshan_105 | D8: 手术处置 | E8: analysis_viz/data/raw/center_data/佛山/GT/standardized_foshan.xlsx | F8: Surgery
A9: analysis_viz/data/derived/figdata/v2_subplots/G1_dataset/G1_llm_case_taxonomy_v1.csv | B9: 佛山 | C9: foshan_106 | D9: 手术处置 | E9: analysis_viz/data/raw/center_data/佛山/GT/standardized_foshan.xlsx | F9: Surgery
A10: analysis_viz/data/derived/figdata/v2_subplots/G1_dataset/G1_llm_case_taxonomy_v1.csv | B10: 佛山 | C10: foshan_107 | D10: 手术处置 | E10: analysis_viz/data/raw/center_data/佛山/GT/standardized_foshan.xlsx | F10: Surgery
A11: analysis_viz/data/derived/figdata/v2_subplots/G1_dataset/G1_llm_case_taxonomy_v1.csv | B11: 佛山 | C11: foshan_108 | D11: 手术处置 | E11: analysis_viz/data/raw/center_data/佛山/GT/standardized_foshan.xlsx | F11: Surgery
